Workbook

Sheet Lista de compras
A1: Proyecto | B1: Casa Los Samanes
A2: Ubicación | B2: Urb. Prueba, parcela 12
A3: Fecha | B3: 4/10/26, 3:14 a. m.
A4: Generado por
A6: Descripción | B6: Cantidad | C6: Und | D6: P. Unitario | E6: Subtotal
A7: Arena | B7: 2.0790066 | C7: m³ | D7: =Precios!C5 -> 30 | E7: =B7*D7 -> 62.370197
A8: Bloque de concreto de 15 cm | B8: 342 | C8: und | D8: =Precios!C6 -> 0 | E8: =B8*D8 -> 0
A9: Boquilla (fragua) | B9: 2.56 | C9: kg | D9: =Precios!C7 -> 0 | E9: =B9*D9 -> 0
A10: Cabilla ø 1/2" de 12 m | B10: 10 | C10: und | D10: =Precios!C8 -> 0 | E10: =B10*D10 -> 0
A11: Cemento (saco de 42,5 kg) | B11: 13 | C11: sacos | D11: =Precios!C9 -> 0 | E11: =B11*D11 -> 0
A12: Cemento (saco de 50 kg) | B12: 9 | C12: sacos | D12: =Precios!C10 -> 9 | E12: =B12*D12 -> 81
A13: Cerámica 60×60 cm | B13: 15 | C13: cajas | D13: =Precios!C11 -> 0 | E13: =B13*D13 -> 0
A14: Clavos de 2 1/2" | B14: 1.728 | C14: kg | D14: =Precios!C12 -> 0 | E14: =B14*D14 -> 0
A15: Clavos de 3" | B15: 1.8 | C15: kg | D15: =Precios!C13 -> 0 | E15: =B15*D15 -> 0
A16: Cuadrilla · Pared de bloque | B16: 3 | C16: días | D16: =Precios!C14 -> 0 | E16: =B16*D16 -> 0
A17: Imprimación asfáltica | B17: 12 | C17: L | D17: =Precios!C15 -> 0 | E17: =B17*D17 -> 0
A18: Lámina de zinc acanalada de 3,66 m | B18: 21 | C18: und | D18: =Precios!C16 -> 0 | E18: =B18*D18 -> 0
... A25: Tornapuntas | B25: 8 | C25: piezas | D25: =Precios!C23 -> 0 | E25: =B25*D25 -> 0
A26: TOTAL | E26: =SUM(E7:E25) -> 143.3702
A28: Cantidades referenciales; verifícalas con tu ingeniero. Criterios de concreto según COVENIN 1753-2006.

Sheet Precios
A1: Precios unitarios de materiales
A2: Edita la columna C (celdas amarillas): las demás hojas se recalculan solas. Si un material tenía varios precios en la app, se usó el más reciente.
A4: Material | B4: Und | C4: Precio unitario
A5: Arena | B5: m³ | C5: 30
A6: Bloque de concreto de 15 cm | B6: und | C6: 0
A7: Boquilla (fragua) | B7: kg | C7: 0
A8: Cabilla ø 1/2" de 12 m | B8: und | C8: 0
A9: Cemento (saco de 42,5 kg) | B9: sacos | C9: 0
A10: Cemento (saco de 50 kg) | B10: sacos | C10: 9
A11: Cerámica 60×60 cm | B11: cajas | C11: 0
A12: Clavos de 2 1/2" | B12: kg | C12: 0
A13: Clavos de 3" | B13: kg | C13: 0
A14: Cuadrilla · Pared de bloque | B14: días | C14: 0
A15: Imprimación asfáltica | B15: L | C15: 0
A16: Lámina de zinc acanalada de 3,66 m | B16: und | C16: 0
... A23: Tornapuntas | B23: piezas | C23: 0

Sheet Resumen por partidas
A1: Resumen por partidas
A2: Casa Los Samanes · Urb. Prueba, parcela 12
A4: Partida / Material | B4: Cantidad | C4: Und | D4: P. Unitario | E4: Subtotal
A5: 1. Columna · 1,08 m³ — Columna f'c 210 (1:2:3, a/c 0.5): 0.3×0.3×3 m × 4, piedra 1"
A6: Cemento (saco de 50 kg) | B6: 8.43696 | C6: sacos | D6: =Precios!C10 -> 9 | E6: =B6*D6 -> 75.93264
A7: Arena (concreto) | B7: 0.5859 | C7: m³ | D7: =Precios!C5 -> 30 | E7: =B7*D7 -> 17.577
A8: Piedra picada 1" (concreto) | B8: 0.87885 | C8: m³ | D8: =Precios!C20 -> 0 | E8: =B8*D8 -> 0
A9: Subtotal partida | E9: =SUM(E6:E8) -> 93.50964
A10: 2. Acero ø 1/2" · 107,53 kg — Acero ø 1/2": 100 m
A11: Cabilla ø 1/2" de 12 m | B11: 10 | C11: und | D11: =Precios!C8 -> 0 | E11: =B11*D11 -> 0
A12: Subtotal partida | E12: =SUM(E11:E11) -> 0
A13: 3. Bloques — Bloque de concreto de 15 cm, 26 m² netos
A14: Bloque de concreto de 15 cm | B14: 342 | C14: und | D14: =Precios!C6 -> 0 | E14: =B14*D14 -> 0
A15: Cemento (pega, saco de 42,5 kg) | B15: 2.7180563 | C15: sacos | D15: =Precios!C9 -> 0 | E15: =B15*D15 -> 0
A16: Arena (pega) | B16: 0.31710656 | C16: m³ | D16: =Precios!C5 -> 30 | E16: =B16*D16 -> 9.5131969
A17: Subtotal partida | E17: =SUM(E14:E16) -> 9.5131969
A18: 4. Friso — Friso interno 1:4: 50 m² × 2 cm
A19: Cemento (friso interno, saco de 42,5 kg) | B19: 10.08 | C19: sacos | D19: =Precios!C9 -> 0 | E19: =B19*D19 -> 0
A20: Arena (friso interno) | B20: 1.176 | C20: m³ | D20: =Precios!C5 -> 30 | E20: =B20*D20 -> 35.28
A21: Subtotal partida | E21: =SUM(E19:E20) -> 35.28
A22: 5. Impermeabilización — Manto asfáltico en 60 m²
A23: Manto asfáltico | B23: 66.6 | C23: m² | D23: =Precios!C18 -> 0 | E23: =B23*D23 -> 0
A24: Imprimación asfáltica | B24: 12 | C24: L | D24: =Precios!C15 -> 0 | E24: =B24*D24 -> 0
A25: Subtotal partida | E25: =SUM(E23:E24) -> 0
A26: 6. Pintura — Caucho en paredes: 80 m², 2 manos, friso nuevo
A27: Pintura caucho (paredes) | B27: 6.16 | C27: gal | D27: =Precios!C21 -> 0 | E27: =B27*D27 -> 0
A28: Subtotal partida | E28: =SUM(E27:E27) -> 0
A29: 7. Cerámica — Cerámica 60×60 cm, junta 3 mm, 20 m²
A30: Cerámica 60×60 cm | B30: 15 | C30: cajas | D30: =Precios!C11 -> 0 | E30: =B30*D30 -> 0
A31: Pego para cerámica (bolsa de 25 kg) | B31: 4 | C31: bolsas | D31: =Precios!C19 -> 0 | E31: =B31*D31 -> 0
A32: Boquilla (fragua) | B32: 2.56 | C32: kg | D32: =Precios!C7 -> 0 | E32: =B32*D32 -> 0
A33: Subtotal partida | E33: =SUM(E30:E32) -> 0
A34: 8. Techo — Lámina de zinc acanalada, 41,76 m² de techo
A35: Lámina de zinc acanalada de 3,66 m | B35: 21 | C35: und | D35: =Precios!C16 -> 0 | E35: =B35*D35 -> 0
A36: Subtotal partida | E36: =SUM(E35:E35) -> 0
A37: 9. Cuadrilla — Pared de bloque: 30 m², 1 cuadrilla(s)
A38: Cuadrilla · Pared de bloque | B38: 3 | C38: días | D38: =Precios!C14 -> 0 | E38: =B38*D38 -> 0
A39: Subtotal partida | E39: =SUM(E38:E38) -> 0
A40: 10. Encofrado — Encofrado Columna: 0.3×0.3×3 m × 4
A41: Tablas de 1"×8"×3 m | B41: 9 | C41: piezas | D41: =Precios!C22 -> 0 | E41: =B41*D41 -> 0
...

Sheet Fórmulas
A1: Fórmulas y datos de cada cálculo
A2: Los resultados son fórmulas vivas de Excel: cambia un dato de entrada (celda amarilla) y se recalculan.
A4: 1. Columna · 1,08 m³ — Columna f'c 210 (1:2:3, a/c 0.5): 0.3×0.3×3 m × 4, piedra 1"
A5: Elemento | B5: Columna | D5: Dato de entrada
A6: Largo | B6: 0.3 | C6: m | D6: Dato de entrada
A7: Ancho | B7: 0.3 | C7: m | D7: Dato de entrada
A8: Alto o espesor | B8: 3 | C8: m | D8: Dato de entrada
A9: Cantidad | B9: 4 | C9: und | D9: Dato de entrada
A10: Separación libre entre barras | B10: 5 | C10: cm | D10: Dato de entrada
A11: f'c (kg/cm²) | B11: 210 | D11: Dato de entrada
A12: Proporción C:A:G | B12: 1:2:3 | D12: Dato de entrada
A13: Relación agua/cemento (a/c) | B13: 0.5 | D13: Dato de entrada
A14: Saco de cemento (kg) | B14: 50 | D14: Dato de entrada
A15: Piedra picada | B15: Recomendada | D15: Dato de entrada
A16: Tipo de concreto | B16: Hecho en obra | D16: Dato de entrada
A17: Desperdicio | B17: 5 | C17: % | D17: Dato de entrada
A18: Partes de cemento | B18: 1 | D18: Dato de entrada
A19: Partes de arena | B19: 2 | D19: Dato de entrada
A20: Partes de grava | B20: 3 | D20: Dato de entrada
A21: Resultados
A22: Volumen neto | B22: =$B$6*$B$7*$B$8*$B$9 -> 1.08 | C22: m³ | D22: Largo × Ancho × Alto × Cantidad
A23: Volumen con desperdicio | B23: =B22*(1+$B$17/100) -> 1.134 | C23: m³ | D23: Volumen neto × (1 + desperdicio/100)
A24: Volumen suelto | B24: =B23*1.55 -> 1.7577 | C24: m³ | D24: V × 1,55 (corrige a material suelto)
A25: Cemento | B25: =B24*$B$18/($B$18+$B$19+$B$20)*1440 -> 421.848 | C25: kg | D25: Vseco × C/(C+A+G) × 1440 kg/m³
A26: Sacos de cemento | B26: =B25/$B$14 -> 8.43696 | C26: sacos | D26: Cemento (kg) ÷ kg por saco
A27: Arena | B27: =B24*$B$19/($B$18+$B$19+$B$20) -> 0.5859 | C27: m³ | D27: Vseco × A/(C+A+G)
A28: Grava / piedra picada | B28: =B24*$B$20/($B$18+$B$19+$B$20) -> 0.87885 | C28: m³ | D28: Vseco × G/(C+A+G)
A29: Agua | B29: =B25*$B$13 -> 210.924 | C29: L | D29: Cemento (kg) × relación a/c
A31: 2. Acero ø 1/2" · 107,53 kg — Acero ø 1/2": 100 m
A32: Método | B32: Por metros lineales | D32: Dato de entrada
A33: Diámetro de cabilla (pulg.) | B33: Recomendada | D33: Dato de entrada
A34: Metros lineales (método 1) | B34: 100 | C34: m | D34: Dato de entrada
A35: Elemento (método 2) | B35: Columna | D35: Dato de entrada
A36: Volumen de concreto (método 2) | B36: 1 | C36: m³ | D36: Dato de entrada
A37: Largo de la varilla | B37: 12 | C37: m | D37: Dato de entrada
A38: Traslapes y desperdicio | B38: 8 | C38: % | D38: Dato de entrada
A39: Cabilla a usar | B39: ø 1/2" | D39: Dato de entrada
A40: Diámetro de la cabilla | B40: 12.7 | C40: mm | D40: Dato de entrada
A41: Resultados
A42: Peso por metro | B42: =$B$40^2/162 -> 0.99561728 | C42: kg/m | D42: d² (mm) ÷ 162
...
